# -----   Исключения  Exceptions  Ошибки   ---------------------------------------------------------------------------------------------------------------------------------------------------------------------------------------------

try:
    pass

# except выполяеться если в try возникла ошибка(Исключение)
except Exeption:
    pass

# второй exсept выполянеться елси возникла ошибка в первом except
except:
    pass

# else выполняеться, если выполнилься полностью блок try без ошибок
else:
    pass

# finally выполняеться в любом случае
finally:
    pass


# -----   Много except   --------------------------------------------------------------------------------------------------------------------------------------------------------------------------------------------------------------------------

try:
    raise ValueError

# будет выполняться тот except с которым сходиться название ошибки
# в нашем случае будет выполняться второй except
except ZeroDivisionError:
    pass
except (ValueError, NameError):
    pass

# -----   except Exeption   ------------------------------------------------------------------------------------------------------------------------------------------------------------------------------------------------------

try:
    raise ValueError

# ValueError yнаследуеться от Exception
# поетому второй except никогда не выполниться
except Exception:
    pass
except ValueError:
    pass

# -----  возвращаение из внутренего обработчика во внешний   reraise   -----------------------------------------------------------------------------------------------------------------------------------------------------------------------------------------------------
# обрабаотываеться и внетреняя ошибка и внешняя
try:
    try:
        raise ValueError("Value Error")
    except Exception:
        # print("INNER")
        raise

except Exception:
    # print("OUTER")
    pass

# -----   BaseExceptionGroup ->  ExceptionGroup -> ValueError   ---------------------------------------------------------------------------------------------------------------------------------------------------------------------------------------------------------------------------
# позволяют поднимать сразу несколько исключений

try:
    pass
except BaseExceptionGroup as a:
    pass
except ExceptionGroup as a:
    pass

# -----   except*   --------------------------------------------------------------------------------------------------------------------------------------------------------------------------------------------------------------------------
# except* обработает только указный тип ошибки из принятой групи ошибок ExceptionGroup
try:
    eg = ExceptionGroup(
        TypeError,
        ValueError,
    )

except* TypeError:
    pass
except* ValueError:
    pass

# -----   создание своего исключения   ----------------------------------------------------------------------------------------------------------------------------------------------------------------
# нужен для получения больше информации при появлении ошибки(исключения)


class MyClass(Exception):
    def __init__(self, value, message="Default Message"):
        self.value = value
        self.message = message
        super().__init__(self.message)


# raise MyClass("text")
